Workbook
Name DatosExternos_1: BD!$A$1:$E$3588
Name DES.1: 'LISTA SABANA'!$G$12
Name DES.1: 'LISTA SABANA'!$G$12
Name DES.2: 'LISTA SABANA'!$I$12
Name DES.2: 'LISTA SABANA'!$I$12

Sheet ÍNDICE
A1: INDICE | H1: Seleccione el Producto a consultar | AV1: =IFERROR(VLOOKUP("*"&$H$3&"*",$A$2:$A$23,1,0),VLOOKUP("*"&$H$3&"*",$B$2:$B$26,1,0)) -> CONECTORES NEUMÁTICOS
A2: {=+HYPERLINK("#"&CELL("direccion",INDIRECT("'LISTA SABANA'!B"&C2)),INDEX('LISTA SABANA'!C:C,C2,1))} -> PLASTICOS | B2: {=+HYPERLINK("#"&CELL("direccion",INDIRECT("'LISTA SABANA'!B"&E2)),INDEX('LISTA SABANA'!C:C,E2,1))} -> ARANDELAS DE COBRE | C2: =+MATCH(D2,'LISTA SABANA'!C:C,0) -> 14 | D2: PLASTICOS | E2: =+MATCH(F2,'LISTA SABANA'!C:C,0) -> 1979 | F2: ARANDELAS DE COBRE | H2: Cambie AQUÍ | AW2: VER NUESTROS COMBOS
A3: {=+HYPERLINK("#"&CELL("direccion",INDIRECT("'LISTA SABANA'!B"&C3)),INDEX('LISTA SABANA'!C:C,C3,1))} -> RESORTES LINEA FERRETERIA | B3: {=+HYPERLINK("#"&CELL("direccion",INDIRECT("'LISTA SABANA'!B"&E3)),INDEX('LISTA SABANA'!C:C,E3,1))} -> ARANDELAS DE ALUMINIO | C3: =+MATCH(D3,'LISTA SABANA'!C:C,0) -> 413 | D3: RESORTES LINEA FERRETERIA | E3: =+MATCH(F3,'LISTA SABANA'!C:C,0) -> 2009 | F3: ARANDELAS DE ALUMINIO | G3: Buscador: | H3: neu | I3: {=+HYPERLINK("#"&CELL("direccion",INDIRECT("'LISTA SABANA'!B"&IFERROR(VLOOKUP(IFERROR(VLOOKUP("*"&H3&"*",$A$2:$A$27,1,0),VLOOKUP("*"&H3&"*",$B$2:$B$27,1,0)),$B$2:$E$27,4,0),VLOOKUP(IFERROR(VLOOKUP("*"&H3&"*",$A$2:$A$27,1,0),VLOOKUP("*"&H3&"*",$B$2:$B$27,1,0)),$A$2:$C$27,3,0)))),IFERROR(VLOOKUP("*"&H3&"*",$A$2:$A$27,1,0),VLOOKUP("*"&H3&"*",$B$2:$B$27,1,0))&" - IR")} -> CONECTORES NEUMÁTICOS - IR | BE3: N° | BF3: Productos
A4: {=+HYPERLINK("#"&CELL("direccion",INDIRECT("'LISTA SABANA'!B"&C4)),INDEX('LISTA SABANA'!C:C,C4,1))} -> RESORTES LINEA COMPLEMENTARIA | B4: {=+HYPERLINK("#"&CELL("direccion",INDIRECT("'LISTA SABANA'!B"&E4)),INDEX('LISTA SABANA'!C:C,E4,1))} -> ARANDELAS DE FIBRA | C4: =+MATCH(D4,'LISTA SABANA'!C:C,0) -> 508 | D4: RESORTES LINEA COMPLEMENTARIA | E4: =+MATCH(F4,'LISTA SABANA'!C:C,0) -> 2037 | F4: ARANDELAS DE FIBRA | H4: BUSQUEDA RAPIDA POR PRODUCTO | BE4: {=+_xlfn._xlws.FILTER(Table_2[Numero],Table_2[Producto]=ÍNDICE!I7,)} -> 4 | BF4: {=+_xlfn.UNIQUE(Table_2[Producto])} -> PLASTICOS
A5: {=+HYPERLINK("#"&CELL("direccion",INDIRECT("'LISTA SABANA'!B"&C5)),INDEX('LISTA SABANA'!C:C,C5,1))} -> RESORTES LINEA PESADA | B5: {=+HYPERLINK("#"&CELL("direccion",INDIRECT("'LISTA SABANA'!B"&E5)),INDEX('LISTA SABANA'!C:C,E5,1))} -> ARANDELAS DE POLIPROPILENO | C5: =+MATCH(D5,'LISTA SABANA'!C:C,0) -> 622 | D5: RESORTES LINEA PESADA | E5: =+MATCH(F5,'LISTA SABANA'!C:C,0) -> 2069 | F5: ARANDELAS DE POLIPROPILENO | H5: Producto: | I5: CONECTORES NEUMÁTICOS | J5: Cambie AQUÍ | BE5: 5 | BF5: RESORTES LINEA FERRETERIA
A6: {=+HYPERLINK("#"&CELL("direccion",INDIRECT("'LISTA SABANA'!B"&C6)),INDEX('LISTA SABANA'!C:C,C6,1))} -> RESORTES LINEA BULONERA | B6: {=+HYPERLINK("#"&CELL("direccion",INDIRECT("'LISTA SABANA'!B"&E6)),INDEX('LISTA SABANA'!C:C,E6,1))} -> PICOS PARA GAS | C6: =+MATCH(D6,'LISTA SABANA'!C:C,0) -> 665 | D6: RESORTES LINEA BULONERA | E6: =+MATCH(F6,'LISTA SABANA'!C:C,0) -> 2363 | F6: PICOS PARA GAS | H6: N°: | I6: 98 | J6: Cambie AQUÍ | BE6: 6 | BF6: RESORTES LINEA COMPLEMENTARIA
A7: {=+HYPERLINK("#"&CELL("direccion",INDIRECT("'LISTA SABANA'!B"&C7)),INDEX('LISTA SABANA'!C:C,C7,1))} -> RESORTES LINEA AUTOMOTOR | B7: {=+HYPERLINK("#"&CELL("direccion",INDIRECT("'LISTA SABANA'!B"&E7)),INDEX('LISTA SABANA'!C:C,E7,1))} -> RETENES SEGURIDAD | C7: =+MATCH(D7,'LISTA SABANA'!C:C,0) -> 702 | D7: RESORTES LINEA AUTOMOTOR | E7: =+MATCH(F7,'LISTA SABANA'!C:C,0) -> 2419 | F7: RETENES SEGURIDAD | G7: 0 | H7: Producto: | I7: =+IFERROR(VLOOKUP("*"&I5&"*",$A$2:$A$27,1,0),VLOOKUP("*"&I5&"*",$B$2:$F$27,1,0)) -> CONECTORES NEUMÁTICOS | L7: =+I6 -> 98 | BE7: 8 | BF7: RESORTES LINEA PESADA
A8: {=+HYPERLINK("#"&CELL("direccion",INDIRECT("'LISTA SABANA'!B"&C8)),INDEX('LISTA SABANA'!C:C,C8,1))} -> RESORTES LINEA HORNO | B8: {=+HYPERLINK("#"&CELL("direccion",INDIRECT("'LISTA SABANA'!B"&E8)),INDEX('LISTA SABANA'!C:C,E8,1))} -> ARANLOCK | C8: =+MATCH(D8,'LISTA SABANA'!C:C,0) -> 800 | D8: RESORTES LINEA HORNO | E8: =+MATCH(F8,'LISTA SABANA'!C:C,0) -> 2435 | F8: ARANLOCK | H8: N° | I8: Descripción | J8: Lista $ | K8: Costo | L8: VENTA | BE8: 9 | BF8: RESORTES LINEA AUTOMOTOR
A9: {=+HYPERLINK("#"&CELL("direccion",INDIRECT("'LISTA SABANA'!B"&C9)),INDEX('LISTA SABANA'!C:C,C9,1))} -> ORING | B9: {=+HYPERLINK("#"&CELL("direccion",INDIRECT("'LISTA SABANA'!B"&E9)),INDEX('LISTA SABANA'!C:C,E9,1))} -> ESPARRAGOS DE ACERO | C9: =+MATCH(D9,'LISTA SABANA'!C:C,0) -> 828 | D9: ORING | E9: =+MATCH(F9,'LISTA SABANA'!C:C,0) -> 2449 | F9: ESPARRAGOS DE ACERO | H9: =+VLOOKUP(IFERROR(VLOOKUP("*"&I5&"*",$A$2:$A$27,1,0),VLOOKUP("*"&I5&"*",$B$2:$F$27,1,0))&I6&"*",BD!$A$2:$E$5000,3,0) -> 98 | I9: =+VLOOKUP(IFERROR(VLOOKUP("*"&I5&"*",$A$2:$A$27,1,0),VLOOKUP("*"&I5&"*",$B$2:$F$27,1,0))&I6&"*",BD!$A$2:$E$5000,4,0) -> Unión doble plástica 8 mm | J9: =+VLOOKUP(IFERROR(VLOOKUP("*"&I5&"*",$A$2:$A$27,1,0),VLOOKUP("*"&I5&"*",$B$2:$B$27,1,0))&I6&"*",BD!$A$2:$E$5000,5,0) -> 999.51 | K9: =+J9-(J9*DES.1) -> 539.7354 | L9: =+VLOOKUP(I7&H9,'LISTA SABANA'!A:I,9,0) -> 971.53 | BE9: 10 | BF9: RESORTES LINEA HORNO
A10: {=+HYPERLINK("#"&CELL("direccion",INDIRECT("'LISTA SABANA'!B"&C10)),INDEX('LISTA SABANA'!C:C,C10,1))} -> CARBONES | B10: {=+HYPERLINK("#"&CELL("direccion",INDIRECT("'LISTA SABANA'!B"&E10)),INDEX('LISTA SABANA'!C:C,E10,1))} -> PASACABLES DE GOMA | C10: =+MATCH(D10,'LISTA SABANA'!C:C,0) -> 978 | D10: CARBONES | E10: =+MATCH(F10,'LISTA SABANA'!C:C,0) -> 2507 | F10: PASACABLES DE GOMA | BE10: 11 | BF10: RESORTES LINEA BULONERA
A11: {=+HYPERLINK("#"&CELL("direccion",INDIRECT("'LISTA SABANA'!B"&C11)),INDEX('LISTA SABANA'!C:C,C11,1))} -> TERMINALES | B11: {=+HYPERLINK("#"&CELL("direccion",INDIRECT("'LISTA SABANA'!B"&E11)),INDEX('LISTA SABANA'!C:C,E11,1))} -> ALEMITES | C11: =+MATCH(D11,'LISTA SABANA'!C:C,0) -> 1037 | D11: TERMINALES | E11: =+MATCH(F11,'LISTA SABANA'!C:C,0) -> 2535 | F11: ALEMITES | BE11: 44 | BF11: SEEGER DIN 471
A12: {=+HYPERLINK("#"&CELL("direccion",INDIRECT("'LISTA SABANA'!B"&C12)),INDEX('LISTA SABANA'!C:C,C12,1))} -> REGATONES | B12: {=+HYPERLINK("#"&CELL("direccion",INDIRECT("'LISTA SABANA'!B"&E12)),INDEX('LISTA SABANA'!C:C,E12,1))} -> CONECTORES NEUMÁTICOS | C12: =+MATCH(D12,'LISTA SABANA'!C:C,0) -> 1121 | D12: REGATONES | E12: =+MATCH(F12,'LISTA SABANA'!C:C,0) -> 2559 | F12: CONECTORES NEUMÁTICOS | BE12: 45 | BF12: SEEGER DIN 472
A13: {=+HYPERLINK("#"&CELL("direccion",INDIRECT("'LISTA SABANA'!B"&C13)),INDEX('LISTA SABANA'!C:C,C13,1))} -> ARANDELAS DE GOMA | B13: {=+HYPERLINK("#"&CELL("direccion",INDIRECT("'LISTA SABANA'!B"&E13)),INDEX('LISTA SABANA'!C:C,E13,1))} -> CONECTORES NUEVA INCORPORACION | C13: =+MATCH(D13,'LISTA SABANA'!C:C,0) -> 1210 | D13: ARANDELAS DE GOMA | E13: =+MATCH(F13,'LISTA SABANA'!C:C,0) -> 2632 | F13: CONECTORES NUEVA INCORPORACION | H13: Fecha Ultima Actualización: | I13: 46140 | J13: Actualización, algunos precios DE LISTA | BE13: 46 | BF13: ORING
A14: {=+HYPERLINK("#"&CELL("direccion",INDIRECT("'LISTA SABANA'!B"&C14)),INDEX('LISTA SABANA'!C:C,C14,1))} -> ARANDELAS DE GOMA LINEA PESADA | B14: {=+HYPERLINK("#"&CELL("direccion",INDIRECT("'LISTA SABANA'!B"&E14)),INDEX('LISTA SABANA'!C:C,E14,1))} -> RACORD - ACOPLES - REDUCCIONES - ENTREROSCAS | C14: =+MATCH(D14,'LISTA SABANA'!C:C,0) -> 1264 | D14: ARANDELAS DE GOMA LINEA PESADA | E14: =+MATCH(F14,'LISTA SABANA'!C:C,0) -> 2682 | F14: RACORD - ACOPLES - REDUCCIONES - ENTREROSCAS | I14: Productos Afectados: | J14: ARANDELAS DE INYECCION | BE14: 47 | BF14: INSERTOS
A15: {=+HYPERLINK("#"&CELL("direccion",INDIRECT("'LISTA SABANA'!B"&C15)),INDEX('LISTA SABANA'!C:C,C15,1))} -> SEEGER DIN 471 | B15: {=+HYPERLINK("#"&CELL("direccion",INDIRECT("'LISTA SABANA'!B"&E15)),INDEX('LISTA SABANA'!C:C,E15,1))} -> TAPONES DE CARTER | C15: =+MATCH(D15,'LISTA SABANA'!C:C,0) -> 1293 | D15: SEEGER DIN 471 | E15: =+MATCH(F15,'LISTA SABANA'!C:C,0) -> 2744 | F15: TAPONES DE CARTER | J15: CONECTORES NEUMÁTICOS | BE15: 62 | BF15: CONEXIÓN DE CHAPA
A16: {=+HYPERLINK("#"&CELL("direccion",INDIRECT("'LISTA SABANA'!B"&C16)),INDEX('LISTA SABANA'!C:C,C16,1))} -> SEEGER DIN 472 | B16: {=+HYPERLINK("#"&CELL("direccion",INDIRECT("'LISTA SABANA'!B"&E16)),INDEX('LISTA SABANA'!C:C,E16,1))} -> ABRAZADERAS C/ GOMA - AC INOXIDABLE | C16: =+MATCH(D16,'LISTA SABANA'!C:C,0) -> 1355 | D16: SEEGER DIN 472 | E16: =+MATCH(F16,'LISTA SABANA'!C:C,0) -> 2771 | F16: ABRAZADERAS C/ GOMA - AC INOXIDABLE | J16: RESORTES LINEA PESADA | BE16: 63 | BF16: TOPES Y TAPONES DE GOMA
A17: {=+HYPERLINK("#"&CELL("direccion",INDIRECT("'LISTA SABANA'!B"&C17)),INDEX('LISTA SABANA'!C:C,C17,1))} -> INSERTOS | B17: {=+HYPERLINK("#"&CELL("direccion",INDIRECT("'LISTA SABANA'!B"&E17)),INDEX('LISTA SABANA'!C:C,E17,1))} -> ABRAZADERAS C/ GOMA - ALUMINIO | C17: =+MATCH(D17,'LISTA SABANA'!C:C,0) -> 1422 | D17: INSERTOS | E17: =+MATCH(F17,'LISTA SABANA'!C:C,0) -> 2790 | F17: ABRAZADERAS C/ GOMA - ALUMINIO | J17: REGATONES | BE17: 65 | BF17: CONECTORES PLASTICOS MANGUERAS
A18: {=+HYPERLINK("#"&CELL("direccion",INDIRECT("'LISTA SABANA'!B"&C18)),INDEX('LISTA SABANA'!C:C,C18,1))} -> TOPES Y TAPONES DE GOMA | B18: {=+HYPERLINK("#"&CELL("direccion",INDIRECT("'LISTA SABANA'!B"&E18)),INDEX('LISTA SABANA'!C:C,E18,1))} -> PERILLAS DE COCINA | C18: =+MATCH(D18,'LISTA SABANA'!C:C,0) -> 1449 | D18: TOPES Y TAPONES DE GOMA | E18: =+MATCH(F18,'LISTA SABANA'!C:C,0) -> 2809 | F18: PERILLAS DE COCINA | J18: TERMINALES | BE18: 66 | BF18: TUERCAS RAPIDAS
A19: {=+HYPERLINK("#"&CELL("direccion",INDIRECT("'LISTA SABANA'!B"&C19)),INDEX('LISTA SABANA'!C:C,C19,1))} -> CHAVETAS | B19: {=+HYPERLINK("#"&CELL("direccion",INDIRECT("'LISTA SABANA'!B"&E19)),INDEX('LISTA SABANA'!C:C,E19,1))} -> UNIONES ORIENTABLES | C19: =+MATCH(D19,'LISTA SABANA'!C:C,0) -> 1516 | D19: CHAVETAS | E19: =+MATCH(F19,'LISTA SABANA'!C:C,0) -> 2870 | F19: UNIONES ORIENTABLES | J19: RESORTES LINEA FERRETERIA | BE19: 67 | BF19: ARANDELAS DE COBRE
A20: {=+HYPERLINK("#"&CELL("direccion",INDIRECT("'LISTA SABANA'!B"&C20)),INDEX('LISTA SABANA'!C:C,C20,1))} -> GANCHOS - CHAVETAS | B20: {=+HYPERLINK("#"&CELL("direccion",INDIRECT("'LISTA SABANA'!B"&E20)),INDEX('LISTA SABANA'!C:C,E20,1))} -> ARANDELAS DE INYECCION | C20: =+MATCH(D20,'LISTA SABANA'!C:C,0) -> 1546 | D20: GANCHOS - CHAVETAS | E20: =+MATCH(F20,'LISTA SABANA'!C:C,0) -> 2910 | F20: ARANDELAS DE INYECCION | J20: CONECTORES NUEVA INCORPORACION | BE20: 68 | BF20: ARANDELAS DE ALUMINIO
A21: {=+HYPERLINK("#"&CELL("direccion",INDIRECT("'LISTA SABANA'!B"&C21)),INDEX('LISTA SABANA'!C:C,C21,1))} -> CHAVETAS PARTIDAS | B21: {=+HYPERLINK("#"&CELL("direccion",INDIRECT("'LISTA SABANA'!B"&E21)),INDEX('LISTA SABANA'!C:C,E21,1))} -> ACCESORIOS DE BRONCE UNION POLIAMIDA | C21: =+MATCH(D21,'LISTA SABANA'!C:C,0) -> 1571 | D21: CHAVETAS PARTIDAS | E21: =+MATCH(F21,'LISTA SABANA'!C:C,0) -> 2951 | F21: ACCESORIOS DE BRONCE UNION POLIAMIDA | J21: UNIONES ORIENTABLES | BE21: 77 | BF21: ARANDELAS DE FIBRA
A22: {=+HYPERLINK("#"&CELL("direccion",INDIRECT("'LISTA SABANA'!B"&C22)),INDEX('LISTA SABANA'!C:C,C22,1))} -> ESPINAS ELASTICAS | B22: {=+HYPERLINK("#"&CELL("direccion",INDIRECT("'LISTA SABANA'!B"&E22)),INDEX('LISTA SABANA'!C:C,E22,1))} -> INTERRUPTORES Y PULSADORES | C22: =+MATCH(D22,'LISTA SABANA'!C:C,0) -> 1608 | D22: ESPINAS ELASTICAS | E22: =+MATCH(F22,'LISTA SABANA'!C:C,0) -> 2985 | F22: INTERRUPTORES Y PULSADORES | J22: RESORTES LINEA COMPLEMENTARIA | BE22: 78 | BF22: ARANDELAS DE POLIPROPILENO
A23: {=+HYPERLINK("#"&CELL("direccion",INDIRECT("'LISTA SABANA'!B"&C23)),INDEX('LISTA SABANA'!C:C,C23,1))} -> CONEXIÓN DE ALUMINIO | B23: {=+HYPERLINK("#"&CELL("direccion",INDIRECT("'LISTA SABANA'!B"&E23)),INDEX('LISTA SABANA'!C:C,E23,1))} -> CLIPS IMPORTADOS | C23: =+MATCH(D23,'LISTA SABANA'!C:C,0) -> 1664 | D23: CONEXIÓN DE ALUMINIO | E23: =+MATCH(F23,'LISTA SABANA'!C:C,0) -> 3031 | F23: CLIPS IMPORTADOS | J23: RETENES SEGURIDAD | BE23: 79 | BF23: SUPLEMENTO 0,2
A24: {=+HYPERLINK("#"&CELL("direccion",INDIRECT("'LISTA SABANA'!B"&C24)),INDEX('LISTA SABANA'!C:C,C24,1))} -> CONEXIONES T EN ALUMINIO | B24: {=+HYPERLINK("#"&CELL("direccion",INDIRECT("'LISTA SABANA'!B"&E24)),INDEX('LISTA SABANA'!C:C,E24,1))} -> TORNILLERIA ESPECIAL | C24: =+MATCH(D24,'LISTA SABANA'!C:C,0) -> 1726 | D24: CONEXIONES T EN ALUMINIO | E24: =+MATCH(F24,'LISTA SABANA'!C:C,0) -> 3354 | F24: TORNILLERIA ESPECIAL | J24: ARANDELAS DE ALUMINIO | BE24: 80 | BF24: SUPLEMENTO 0,8
A25: {=+HYPERLINK("#"&CELL("direccion",INDIRECT("'LISTA SABANA'!B"&C25)),INDEX('LISTA SABANA'!C:C,C25,1))} -> CONECTORES PLASTICOS MANGUERAS | B25: {=+HYPERLINK("#"&CELL("direccion",INDIRECT("'LISTA SABANA'!B"&E25)),INDEX('LISTA SABANA'!C:C,E25,1))} -> TUERCAS RAPIDAS NUEVAS | C25: =+MATCH(D25,'LISTA SABANA'!C:C,0) -> 1810 | D25: CONECTORES PLASTICOS MANGUERAS | E25: =+MATCH(F25,'LISTA SABANA'!C:C,0) -> 3433 | F25: TUERCAS RAPIDAS NUEVAS | J25: TAPONES DE CARTER | BE25: 81 | BF25: RACORD - ACOPLES - REDUCCIONES - ENTREROSCAS
A26: {=+HYPERLINK("#"&CELL("direccion",INDIRECT("'LISTA SABANA'!B"&C26)),INDEX('LISTA SABANA'!C:C,C26,1))} -> TUERCAS RAPIDAS | B26: {=+HYPERLINK("#"&CELL("direccion",INDIRECT("'LISTA SABANA'!B"&E26)),INDEX('LISTA SABANA'!C:C,E26,1))} -> CONECTORES DE COMBUSTIBLE | C26: =+MATCH(D26,'LISTA SABANA'!C:C,0) -> 1887 | D26: TUERCAS RAPIDAS | E26: =+MATCH(F26,'LISTA SABANA'!C:C,0) -> 3470 | F26: CONECTORES DE COMBUSTIBLE | J26: ALEMITES | BE26: 86 | BF26: TERMINALES
... A28: {=+HYPERLINK("#"&CELL("direccion",INDIRECT("'LISTA SABANA'!B"&C28)),INDEX('LISTA SABANA'!C:C,C28,1))} -> TARUGOS ESTRIADOS | B28: {=+HYPERLINK("#"&CELL("direccion",INDIRECT("'LISTA SABANA'!B"&E28)),INDEX('LISTA SABANA'!C:C,E28,1))} -> SUPLEMENTO 0,8 | C28: =+MATCH(D28,'LISTA SABANA'!C:C,0) -> 1945 | D28: TARUGOS ESTRIADOS | E28: =+MATCH(F28,'LISTA SABANA'!C:C,0) -> 2256 | F28: SUPLEMENTO 0,8 | J28: CARBONES | BE28: 89 | BF28: ARANDELAS DE GOMA LINEA PESADA
J29: INSERTOS | BE29: 90 | BF29: CHAVETAS
J30: PLASTICOS | BE30: 91 | BF30: GANCHOS - CHAVETAS
J31: SUPLEMENTO 0,2 | BE31: 92 | BF31: CARBONES
J32: SUPLEMENTO 0,8 | BE32: 97 | BF32: ESPINAS ELASTICAS
J33: SEEGER DIN 472 | BE33: 98 | BF33: TARUGOS ESTRIADOS
J34: ESPARRAGOS DE ACERO | BE34: 99 | BF34: RETENES SEGURIDAD
J35: RACORD - ACOPLES - REDUCCIONES - ENTREROSCAS | BE35: 100 | BF35: ARANLOCK
J36: RESORTES LINEA BULONERA | BE36: 101 | BF36: ESPARRAGOS DE ACERO
J37: PERILLAS DE COCINA | BE37: 108 | BF37: PASACABLES DE GOMA
J38: INTERRUPTORES Y PULSADORES | BE38: 109 | BF38: CHAVETAS PARTIDAS
J39: CONECTORES PLASTICOS MANGUERAS | BE39: 110 | BF39: ALEMITES
J40: CONECTORES DE COMBUSTIBLE | BE40: 111 | BF40: CONECTORES NEUMÁTICOS
BE41: 140 | BF41: CONECTORES NUEVA INCORPORACION
...

Sheet LISTA SABANA
J1: Volver al
J2: Indice
D3: Fecha Última Actualización: | E3: =+ÍNDICE!I13 -> 46140
C5: FABRICA Y DISTRIBUIDORA MAXIFER | G5: Agregar IVA? | L5: * *
G7: NO
L8: * *
C11: LISTA SABANA | G11: Descuento: | I11: VENTA | L11: * *
C12: NUMERO | D12: DESCRIPCIÓN | E12: Precio de Lista | G12: 0.46 | I12: 0.8
A14: 1 | C14: =+VLOOKUP(A14,BD!$G:$H,2,0) -> PLASTICOS
A15: PLASTICOS1 | C15: =+VLOOKUP(A15,BD!$A$2:$E$3988,3,0) -> 1 | D15: =+VLOOKUP(A15,BD!$A$2:$E$3988,4,0) -> Grampa tapizado R11- R18 | E15: =+VLOOKUP(A15,BD!$A$2:$E$3988,5,0) -> 1159.02 | G15: =IF($G$7="SI",ROUND(E15-(E15*DES.1),2)*1.21,ROUND(E15-(E15*DES.1),2)) -> 625.87 | I15: {=+ROUND(G15+(G15*DES.2),2)} -> 1126.57 | O15: =+IFERROR(VLOOKUP(A15,Imagen!A:B,2,0),"") -> http://http2.mlstatic.com/D_708492-MLA72045130481_102023-F.jpg
A16: PLASTICOS2 | C16: =+VLOOKUP(A16,BD!$A$2:$E$3988,3,0) -> 2 | D16: =+VLOOKUP(A16,BD!$A$2:$E$3988,4,0) -> Grampa tapizadoDuna-128-147 | E16: =+VLOOKUP(A16,BD!$A$2:$E$3988,5,0) -> 578.93 | G16: =IF($G$7="SI",ROUND(E16-(E16*DES.1),2)*1.21,ROUND(E16-(E16*DES.1),2)) -> 312.62 | I16: {=+ROUND(G16+(G16*DES.2),2)} -> 562.72 | O16: =+IFERROR(VLOOKUP(A16,Imagen!A:B,2,0),"") -> http://http2.mlstatic.com/D_785905-MLA71988387406_102023-F.jpg
A17: PLASTICOS3 | C17: =+VLOOKUP(A17,BD!$A$2:$E$3988,3,0) -> 3 | D17: =+VLOOKUP(A17,BD!$A$2:$E$3988,4,0) -> Tuerca autorros. FIAT-RENAULT | E17: =+VLOOKUP(A17,BD!$A$2:$E$3988,5,0) -> 629.53 | G17: =IF($G$7="SI",ROUND(E17-(E17*DES.1),2)*1.21,ROUND(E17-(E17*DES.1),2)) -> 339.95 | I17: {=+ROUND(G17+(G17*DES.2),2)} -> 611.91 | O17: =+IFERROR(VLOOKUP(A17,Imagen!A:B,2,0),"") -> http://http2.mlstatic.com/D_878027-MLA72239756252_102023-F.jpg
A18: PLASTICOS4 | C18: =+VLOOKUP(A18,BD!$A$2:$E$3988,3,0) -> 4 | D18: =+VLOOKUP(A18,BD!$A$2:$E$3988,4,0) -> Fijacion consola GACELL | E18: =+VLOOKUP(A18,BD!$A$2:$E$3988,5,0) -> 654.85 | G18: =IF($G$7="SI",ROUND(E18-(E18*DES.1),2)*1.21,ROUND(E18-(E18*DES.1),2)) -> 353.62 | I18: {=+ROUND(G18+(G18*DES.2),2)} -> 636.52 | O18: =+IFERROR(VLOOKUP(A18,Imagen!A:B,2,0),"") -> http://http2.mlstatic.com/D_741302-MLA71988387408_102023-F.jpg
A19: PLASTICOS5 | C19: =+VLOOKUP(A19,BD!$A$2:$E$3988,3,0) -> 5 | D19: =+VLOOKUP(A19,BD!$A$2:$E$3988,4,0) -> Fijacion OPTICA 128 | E19: =+VLOOKUP(A19,BD!$A$2:$E$3988,5,0) -> 727.61 | G19: =IF($G$7="SI",ROUND(E19-(E19*DES.1),2)*1.21,ROUND(E19-(E19*DES.1),2)) -> 392.91 | I19: {=+ROUND(G19+(G19*DES.2),2)} -> 707.24 | O19: =+IFERROR(VLOOKUP(A19,Imagen!A:B,2,0),"") -> http://http2.mlstatic.com/D_986792-MLA72240891774_102023-F.jpg
A20: PLASTICOS6 | C20: =+VLOOKUP(A20,BD!$A$2:$E$3988,3,0) -> 6 | D20: =+VLOOKUP(A20,BD!$A$2:$E$3988,4,0) -> Tuerca autorros. GACELL | E20: =+VLOOKUP(A20,BD!$A$2:$E$3988,5,0) -> 914.71 | G20: =IF($G$7="SI",ROUND(E20-(E20*DES.1),2)*1.21,ROUND(E20-(E20*DES.1),2)) -> 493.94 | I20: {=+ROUND(G20+(G20*DES.2),2)} -> 889.09 | O20: =+IFERROR(VLOOKUP(A20,Imagen!A:B,2,0),"") -> http://http2.mlstatic.com/D_953256-MLA71988435968_102023-F.jpg
A21: PLASTICOS7 | C21: =+VLOOKUP(A21,BD!$A$2:$E$3988,3,0) -> 7 | D21: =+VLOOKUP(A21,BD!$A$2:$E$3988,4,0) -> Fijacion patente FIAT | E21: =+VLOOKUP(A21,BD!$A$2:$E$3988,5,0) -> 578.93 | G21: =IF($G$7="SI",ROUND(E21-(E21*DES.1),2)*1.21,ROUND(E21-(E21*DES.1),2)) -> 312.62 | I21: {=+ROUND(G21+(G21*DES.2),2)} -> 562.72 | O21: =+IFERROR(VLOOKUP(A21,Imagen!A:B,2,0),"") -> http://http2.mlstatic.com/D_778884-MLA71988387412_102023-F.jpg
A22: PLASTICOS8 | C22: =+VLOOKUP(A22,BD!$A$2:$E$3988,3,0) -> 8 | D22: =+VLOOKUP(A22,BD!$A$2:$E$3988,4,0) -> Registro faro 125 | E22: =+VLOOKUP(A22,BD!$A$2:$E$3988,5,0) -> 654.85 | G22: =IF($G$7="SI",ROUND(E22-(E22*DES.1),2)*1.21,ROUND(E22-(E22*DES.1),2)) -> 353.62 | I22: {=+ROUND(G22+(G22*DES.2),2)} -> 636.52 | O22: =+IFERROR(VLOOKUP(A22,Imagen!A:B,2,0),"") -> http://http2.mlstatic.com/D_881846-MLA71988387472_102023-F.jpg
A23: PLASTICOS9 | C23: =+VLOOKUP(A23,BD!$A$2:$E$3988,3,0) -> 9 | D23: =+VLOOKUP(A23,BD!$A$2:$E$3988,4,0) -> Tuerca autorroscante FIAT | E23: =+VLOOKUP(A23,BD!$A$2:$E$3988,5,0) -> 680.9 | G23: =IF($G$7="SI",ROUND(E23-(E23*DES.1),2)*1.21,ROUND(E23-(E23*DES.1),2)) -> 367.69 | I23: {=+ROUND(G23+(G23*DES.2),2)} -> 661.84 | O23: =+IFERROR(VLOOKUP(A23,Imagen!A:B,2,0),"") -> http://http2.mlstatic.com/D_647342-MLA72293218763_102023-F.jpg
A24: PLASTICOS10 | C24: =+VLOOKUP(A24,BD!$A$2:$E$3988,3,0) -> 10 | D24: =+VLOOKUP(A24,BD!$A$2:$E$3988,4,0) -> Fijacion capot 125 | E24: =+VLOOKUP(A24,BD!$A$2:$E$3988,5,0) -> 771.26 | G24: =IF($G$7="SI",ROUND(E24-(E24*DES.1),2)*1.21,ROUND(E24-(E24*DES.1),2)) -> 416.48 | I24: {=+ROUND(G24+(G24*DES.2),2)} -> 749.66 | O24: =+IFERROR(VLOOKUP(A24,Imagen!A:B,2,0),"") -> http://http2.mlstatic.com/D_724144-MLA72292952705_102023-F.jpg
A25: PLASTICOS11 | C25: =+VLOOKUP(A25,BD!$A$2:$E$3988,3,0) -> 11 | D25: =+VLOOKUP(A25,BD!$A$2:$E$3988,4,0) -> Tuerca parrilla DUNA- UNO | E25: =+VLOOKUP(A25,BD!$A$2:$E$3988,5,0) -> 917.77 | G25: =IF($G$7="SI",ROUND(E25-(E25*DES.1),2)*1.21,ROUND(E25-(E25*DES.1),2)) -> 495.6 | I25: {=+ROUND(G25+(G25*DES.2),2)} -> 892.08 | O25: =+IFERROR(VLOOKUP(A25,Imagen!A:B,2,0),"") -> http://http2.mlstatic.com/D_790405-MLA72292952961_102023-F.jpg
A26: PLASTICOS12 | C26: =+VLOOKUP(A26,BD!$A$2:$E$3988,3,0) -> 12 | D26: =+VLOOKUP(A26,BD!$A$2:$E$3988,4,0) -> Tuerca autorroc. PEUGEOT | E26: =+VLOOKUP(A26,BD!$A$2:$E$3988,5,0) -> 933.24 | G26: =IF($G$7="SI",ROUND(E26-(E26*DES.1),2)*1.21,ROUND(E26-(E26*DES.1),2)) -> 503.95 | I26: {=+ROUND(G26+(G26*DES.2),2)} -> 907.11 | O26: =+IFERROR(VLOOKUP(A26,Imagen!A:B,2,0),"") -> http://http2.mlstatic.com/D_780043-MLA72292972855_102023-F.jpg
... A412: PLASTICOS402 | C412: =+VLOOKUP(A412,BD!$A$2:$E$3988,3,0) -> 402 | D412: =+VLOOKUP(A412,BD!$A$2:$E$3988,4,0) -> fijación paragolpes y pasaruedas toyota hilux, corrolla, etios | E412: =+VLOOKUP(A412,BD!$A$2:$E$3988,5,0) -> 2127.79 | G412: =IF($G$7="SI",ROUND(E412-(E412*DES.1),2)*1.21,ROUND(E412-(E412*DES.1),2)) -> 1149.01 | I412: {=+ROUND(G412+(G412*DES.2),2)} -> 2068.22 | O412: =+IFERROR(VLOOKUP(A412,Imagen!A:B,2,0),"")
A413: =+A14+1 -> 2 | C413: =+VLOOKUP(A413,BD!$G:$H,2,0) -> RESORTES LINEA FERRETERIA | O413: =+IFERROR(VLOOKUP(A413,Imagen!A:B,2,0),"")
A414: RESORTES LINEA FERRETERIA1 | C414: =+VLOOKUP(A414,BD!$A$2:$E$3988,3,0) -> 1 | D414: =+VLOOKUP(A414,BD!$A$2:$E$3988,4,0) -> 0,5 x 4,5 x 30 - Expansión | E414: =+VLOOKUP(A414,BD!$A$2:$E$3988,5,0) -> 1128 | G414: =IF($G$7="SI",ROUND(E414-(E414*DES.1),2)*1.21,ROUND(E414-(E414*DES.1),2)) -> 609.12 | I414: {=+ROUND(G414+(G414*DES.2),2)} -> 1096.42 | O414: =+IFERROR(VLOOKUP(A414,Imagen!A:B,2,0),"") -> http://http2.mlstatic.com/D_625707-MLA72113085111_102023-F.jpg
A415: RESORTES LINEA FERRETERIA2 | C415: =+VLOOKUP(A415,BD!$A$2:$E$3988,3,0) -> 2 | D415: =+VLOOKUP(A415,BD!$A$2:$E$3988,4,0) -> 0,5 x 6 x 50 - Expansión | E415: =+VLOOKUP(A415,BD!$A$2:$E$3988,5,0) -> 1361.26 | G415: =IF($G$7="SI",ROUND(E415-(E415*DES.1),2)*1.21,ROUND(E415-(E415*DES.1),2)) -> 735.08 | I415: {=+ROUND(G415+(G415*DES.2),2)} -> 1323.14 | O415: =+IFERROR(VLOOKUP(A415,Imagen!A:B,2,0),"") -> http://http2.mlstatic.com/D_854113-MLA72113085113_102023-F.jpg
A416: RESORTES LINEA FERRETERIA3 | C416: =+VLOOKUP(A416,BD!$A$2:$E$3988,3,0) -> 3 | D416: =+VLOOKUP(A416,BD!$A$2:$E$3988,4,0) -> 0,6 x 7 x 30 - Expansión | E416: =+VLOOKUP(A416,BD!$A$2:$E$3988,5,0) -> 1128 | G416: =IF($G$7="SI",ROUND(E416-(E416*DES.1),2)*1.21,ROUND(E416-(E416*DES.1),2)) -> 609.12 | I416: {=+ROUND(G416+(G416*DES.2),2)} -> 1096.42 | O416: =+IFERROR(VLOOKUP(A416,Imagen!A:B,2,0),"") -> http://http2.mlstatic.com/D_989357-MLA72112882997_102023-F.jpg
A417: RESORTES LINEA FERRETERIA4 | C417: =+VLOOKUP(A417,BD!$A$2:$E$3988,3,0) -> 4 | D417: =+VLOOKUP(A417,BD!$A$2:$E$3988,4,0) -> 0,6 x 8 x 50 - Expansión | E417: =+VLOOKUP(A417,BD!$A$2:$E$3988,5,0) -> 1112.12 | G417: =IF($G$7="SI",ROUND(E417-(E417*DES.1),2)*1.21,ROUND(E417-(E417*DES.1),2)) -> 600.54 | I417: {=+ROUND(G417+(G417*DES.2),2)} -> 1080.97 | O417: =+IFERROR(VLOOKUP(A417,Imagen!A:B,2,0),"") -> http://http2.mlstatic.com/D_890937-MLA72112834605_102023-F.jpg
A418: RESORTES LINEA FERRETERIA5 | C418: =+VLOOKUP(A418,BD!$A$2:$E$3988,3,0) -> 5 | D418: =+VLOOKUP(A418,BD!$A$2:$E$3988,4,0) -> 0,8 x 6 x 50 - Expansión | E418: =+VLOOKUP(A418,BD!$A$2:$E$3988,5,0) -> 1112.12 | G418: =IF($G$7="SI",ROUND(E418-(E418*DES.1),2)*1.21,ROUND(E418-(E418*DES.1),2)) -> 600.54 | I418: {=+ROUND(G418+(G418*DES.2),2)} -> 1080.97 | O418: =+IFERROR(VLOOKUP(A418,Imagen!A:B,2,0),"") -> http://http2.mlstatic.com/D_721810-MLA72113085115_102023-F.jpg
A419: RESORTES LINEA FERRETERIA6 | C419: =+VLOOKUP(A419,BD!$A$2:$E$3988,3,0) -> 6 | D419: =+VLOOKUP(A419,BD!$A$2:$E$3988,4,0) -> 0,8 x 8 x 50 - Expansión | E419: =+VLOOKUP(A419,BD!$A$2:$E$3988,5,0) -> 1165.72 | G419: =IF($G$7="SI",ROUND(E419-(E419*DES.1),2)*1.21,ROUND(E419-(E419*DES.1),2)) -> 629.49 | I419: {=+ROUND(G419+(G419*DES.2),2)} -> 1133.08 | O419: =+IFERROR(VLOOKUP(A419,Imagen!A:B,2,0),"") -> http://http2.mlstatic.com/D_839781-MLA72053880672_102023-F.jpg
A420: RESORTES LINEA FERRETERIA7 | C420: =+VLOOKUP(A420,BD!$A$2:$E$3988,3,0) -> 7 | D420: =+VLOOKUP(A420,BD!$A$2:$E$3988,4,0) -> 0,8 x 10 x 50 - Expansión | E420: =+VLOOKUP(A420,BD!$A$2:$E$3988,5,0) -> 1378.67 | G420: =IF($G$7="SI",ROUND(E420-(E420*DES.1),2)*1.21,ROUND(E420-(E420*DES.1),2)) -> 744.48 | I420: {=+ROUND(G420+(G420*DES.2),2)} -> 1340.06 | O420: =+IFERROR(VLOOKUP(A420,Imagen!A:B,2,0),"") -> http://http2.mlstatic.com/D_708588-MLA72112834607_102023-F.jpg
A421: RESORTES LINEA FERRETERIA8 | C421: =+VLOOKUP(A421,BD!$A$2:$E$3988,3,0) -> 8 | D421: =+VLOOKUP(A421,BD!$A$2:$E$3988,4,0) -> 0,8 x 10 x 100 - Expansión | E421: =+VLOOKUP(A421,BD!$A$2:$E$3988,5,0) -> 2116.64 | G421: =IF($G$7="SI",ROUND(E421-(E421*DES.1),2)*1.21,ROUND(E421-(E421*DES.1),2)) -> 1142.99 | I421: {=+ROUND(G421+(G421*DES.2),2)} -> 2057.38 | O421: =+IFERROR(VLOOKUP(A421,Imagen!A:B,2,0),"") -> http://http2.mlstatic.com/D_790933-MLA72112961125_102023-F.jpg
A422: RESORTES LINEA FERRETERIA9 | C422: =+VLOOKUP(A422,BD!$A$2:$E$3988,3,0) -> 9 | D422: =+VLOOKUP(A422,BD!$A$2:$E$3988,4,0) -> 1 x 8 x 40 - Expansión | E422: =+VLOOKUP(A422,BD!$A$2:$E$3988,5,0) -> 1632.32 | G422: =IF($G$7="SI",ROUND(E422-(E422*DES.1),2)*1.21,ROUND(E422-(E422*DES.1),2)) -> 881.45 | I422: {=+ROUND(G422+(G422*DES.2),2)} -> 1586.61 | O422: =+IFERROR(VLOOKUP(A422,Imagen!A:B,2,0),"") -> http://http2.mlstatic.com/D_843566-MLA72053883038_102023-F.jpg
A423: RESORTES LINEA FERRETERIA10 | C423: =+VLOOKUP(A423,BD!$A$2:$E$3988,3,0) -> 10 | D423: =+VLOOKUP(A423,BD!$A$2:$E$3988,4,0) -> 1 x 8 x 100 - Expansión | E423: =+VLOOKUP(A423,BD!$A$2:$E$3988,5,0) -> 2331.84 | G423: =IF($G$7="SI",ROUND(E423-(E423*DES.1),2)*1.21,ROUND(E423-(E423*DES.1),2)) -> 1259.19 | I423: {=+ROUND(G423+(G423*DES.2),2)} -> 2266.54 | O423: =+IFERROR(VLOOKUP(A423,Imagen!A:B,2,0),"") -> http://http2.mlstatic.com/D_930418-MLA72112834643_102023-F.jpg
A424: RESORTES LINEA FERRETERIA11 | C424: =+VLOOKUP(A424,BD!$A$2:$E$3988,3,0) -> 11 | D424: =+VLOOKUP(A424,BD!$A$2:$E$3988,4,0) -> 1 x 10 x 70 - Expansión | E424: =+VLOOKUP(A424,BD!$A$2:$E$3988,5,0) -> 2331.84 | G424: =IF($G$7="SI",ROUND(E424-(E424*DES.1),2)*1.21,ROUND(E424-(E424*DES.1),2)) -> 1259.19 | I424: {=+ROUND(G424+(G424*DES.2),2)} -> 2266.54 | O424: =+IFERROR(VLOOKUP(A424,Imagen!A:B,2,0),"") -> http://http2.mlstatic.com/D_929167-MLA72112834641_102023-F.jpg
A425: RESORTES LINEA FERRETERIA12 | C425: =+VLOOKUP(A425,BD!$A$2:$E$3988,3,0) -> 12 | D425: =+VLOOKUP(A425,BD!$A$2:$E$3988,4,0) -> 1 x 10 x 120 - Expansión | E425: =+VLOOKUP(A425,BD!$A$2:$E$3988,5,0) -> 2690.44 | G425: =IF($G$7="SI",ROUND(E425-(E425*DES.1),2)*1.21,ROUND(E425-(E425*DES.1),2)) -> 1452.84 | I425: {=+ROUND(G425+(G425*DES.2),2)} -> 2615.11 | O425: =+IFERROR(VLOOKUP(A425,Imagen!A:B,2,0),"") -> http://http2.mlstatic.com/D_687934-MLA72112834645_102023-F.jpg
... A507: RESORTES LINEA FERRETERIA103 | C507: =+VLOOKUP(A507,BD!$A$2:$E$3988,3,0) -> 103 | D507: =+VLOOKUP(A507,BD!$A$2:$E$3988,4,0) -> 1,5 x 11 x 20 - Compresión | E507: =+VLOOKUP(A507,BD!$A$2:$E$3988,5,0) -> 940 | G507: =IF($G$7="SI",ROUND(E507-(E507*DES.1),2)*1.21,ROUND(E507-(E507*DES.1),2)) -> 507.6 | I507: {=+ROUND(G507+(G507*DES.2),2)} -> 913.68 | O507: =+IFERROR(VLOOKUP(A507,Imagen!A:B,2,0),"") -> http://http2.mlstatic.com/D_781113-MLA72112883873_102023-F.jpg
A508: =+A413+1 -> 3 | C508: =+VLOOKUP(A508,BD!$G:$H,2,0) -> RESORTES LINEA COMPLEMENTARIA | O508: =+IFERROR(VLOOKUP(A508,Imagen!A:B,2,0),"")
A509: RESORTES LINEA COMPLEMENTARIA269 | C509: =+VLOOKUP(A509,BD!$A$2:$E$3988,3,0) -> 269 | D509: =+VLOOKUP(A509,BD!$A$2:$E$3988,4,0) -> TIJERA PODAR - Expansión | E509: =+VLOOKUP(A509,BD!$A$2:$E$3988,5,0) -> 3408.08 | G509: =IF($G$7="SI",ROUND(E509-(E509*DES.1),2)*1.21,ROUND(E509-(E509*DES.1),2)) -> 1840.36 | I509: {=+ROUND(G509+(G509*DES.2),2)} -> 3312.65 | O509: =+IFERROR(VLOOKUP(A509,Imagen!A:B,2,0),"")
A510: RESORTES LINEA COMPLEMENTARIA270 | C510: =+VLOOKUP(A510,BD!$A$2:$E$3988,3,0) -> 270 | D510: =+VLOOKUP(A510,BD!$A$2:$E$3988,4,0) -> 0,3 x 3 x 15 - Expansión | E510: =+VLOOKUP(A510,BD!$A$2:$E$3988,5,0) -> 933.16 | G510: =IF($G$7="SI",ROUND(E510-(E510*DES.1),2)*1.21,ROUND(E510-(E510*DES.1),2)) -> 503.91 | I510: {=+ROUND(G510+(G510*DES.2),2)} -> 907.04 | O510: =+IFERROR(VLOOKUP(A510,Imagen!A:B,2,0),"") -> http://http2.mlstatic.com/D_910001-MLA72112884111_102023-F.jpg
A511: RESORTES LINEA COMPLEMENTARIA271 | C511: =+VLOOKUP(A511,BD!$A$2:$E$3988,3,0) -> 271 | D511: =+VLOOKUP(A511,BD!$A$2:$E$3988,4,0) -> 0,3 x 4,5 x 22 - Expansión | E511: =+VLOOKUP(A511,BD!$A$2:$E$3988,5,0) -> 933.16 | G511: =IF($G$7="SI",ROUND(E511-(E511*DES.1),2)*1.21,ROUND(E511-(E511*DES.1),2)) -> 503.91 | I511: {=+ROUND(G511+(G511*DES.2),2)} -> 907.04 | O511: =+IFERROR(VLOOKUP(A511,Imagen!A:B,2,0),"") -> http://http2.mlstatic.com/D_642975-MLA72113086249_102023-F.jpg
...

Sheet NUESTROS COMBOS
B1: NUESTROS SURTIDOS | G1: OPCION REDUCIDA | K1: PERSONALIZÁ TU COMBO | L1: *Todos los Surtidos incluyen el exhibidor + las gavetas y un stock inicial de toda la mercadería
B2: Codigo | C2: SURTIDO | D2: Importe P. Lista Cant. Estándar | E2: Importe Final c/descuento | F2: Cantidades Estándar | G2: Surtido Reducido | H2: Importe Final c/descuento | I2: Cant. Reducido | J2: Total Piezas | K2: ENLACE WEB
B3: PL CH. | C3: Plasticos Chico | D3: 865717.51 | E3: =+'NUESTROS COMBOS'!$D3-('NUESTROS COMBOS'!$D3*$M$4) -> 467487.46 | F3: 11 | G3: 281050.23 | H3: =+Table_1[[#This Row],[Surtido Reducido]]-(Table_1[[#This Row],[Surtido Reducido]]*$M$4) -> 151767.12 | I3: 3 | J3: 274 | K3: =+HYPERLINK(Q3,"IR - Comprar y/o Personalizar") -> IR - Comprar y/o Personalizar | M3: Descuento: | Q3: https://www.fabricamaxifer.com/plasticos-chico.html
B4: PL INT 1 | C4: Plasticos Int.1 | D4: 1148270.3 | E4: =+'NUESTROS COMBOS'!$D4-('NUESTROS COMBOS'!$D4*$M$4) -> 620065.97 | F4: 6 - 4 | G4: 653398.2 | H4: =+Table_1[[#This Row],[Surtido Reducido]]-(Table_1[[#This Row],[Surtido Reducido]]*$M$4) -> 352835.03 | I4: 3 | J4: 544 | K4: =+HYPERLINK(Q4,"IR - Comprar y/o Personalizar") -> IR - Comprar y/o Personalizar | M4: =+DES.1 -> 0.46 | Q4: https://www.fabricamaxifer.com/plasticos-int-1.html
B5: PL INT 2 | C5: Plasticos Int.2 | D5: 1294240.9 | E5: =+'NUESTROS COMBOS'!$D5-('NUESTROS COMBOS'!$D5*$M$4) -> 698890.1 | F5: 6 - 4 | G5: 739777.44 | H5: =+Table_1[[#This Row],[Surtido Reducido]]-(Table_1[[#This Row],[Surtido Reducido]]*$M$4) -> 399479.82 | I5: 3 | J5: 526 | K5: =+HYPERLINK(Q5,"IR - Comprar y/o Personalizar") -> IR - Comprar y/o Personalizar | Q5: https://www.fabricamaxifer.com/plasticos-int-2.html
B6: PL COMP. | C6: Plasticos Completo | D6: 2412511.2 | E6: =+'NUESTROS COMBOS'!$D6-('NUESTROS COMBOS'!$D6*$M$4) -> 1302756.1 | F6: 6 - 4 | G6: 1363175.6 | H6: =+Table_1[[#This Row],[Surtido Reducido]]-(Table_1[[#This Row],[Surtido Reducido]]*$M$4) -> 736114.85 | I6: 3 | J6: 1069 | K6: =+HYPERLINK(Q6,"IR - Comprar y/o Personalizar") -> IR - Comprar y/o Personalizar | Q6: https://www.fabricamaxifer.com/plasticos-completo.html
B7: CL. IMP 1 | C7: Clips Importados 1 | D7: 833999.68 | E7: =+'NUESTROS COMBOS'!$D7-('NUESTROS COMBOS'!$D7*$M$4) -> 450359.83 | F7: 4 | G7: 651749.76 | H7: =+Table_1[[#This Row],[Surtido Reducido]]-(Table_1[[#This Row],[Surtido Reducido]]*$M$4) -> 351944.87 | I7: 3 | J7: 486 | K7: =+HYPERLINK(Q7,"IR - Comprar y/o Personalizar") -> IR - Comprar y/o Personalizar | Q7: https://www.fabricamaxifer.com/clips-importados-1.html
B8: CL. IMP 2 | C8: Clips Importados 2 | D8: 846520.84 | E8: =+'NUESTROS COMBOS'!$D8-('NUESTROS COMBOS'!$D8*$M$4) -> 457121.25 | F8: 4 | G8: 661140.63 | H8: =+Table_1[[#This Row],[Surtido Reducido]]-(Table_1[[#This Row],[Surtido Reducido]]*$M$4) -> 357015.94 | I8: 3 | J8: 492 | K8: =+HYPERLINK(Q8,"IR - Comprar y/o Personalizar") -> IR - Comprar y/o Personalizar | Q8: https://www.fabricamaxifer.com/clips-importados-2.html
B9: CL. IMP COM | C9: Clips Importados Completo | D9: 1680520.5 | E9: =+'NUESTROS COMBOS'!$D9-('NUESTROS COMBOS'!$D9*$M$4) -> 907481.08 | F9: 4 | G9: 1312890.4 | H9: =+Table_1[[#This Row],[Surtido Reducido]]-(Table_1[[#This Row],[Surtido Reducido]]*$M$4) -> 708960.81 | I9: 3 | J9: 978 | K9: =+HYPERLINK(Q9,"IR - Comprar y/o Personalizar") -> IR - Comprar y/o Personalizar | Q9: https://www.fabricamaxifer.com/clips-importados-completo.html
B10: RES. LF | C10: Resortes Lf | D10: 681190.56 | E10: =+'NUESTROS COMBOS'!$D10-('NUESTROS COMBOS'!$D10*$M$4) -> 367842.9 | F10: 4 | G10: 385595.28 | H10: =+Table_1[[#This Row],[Surtido Reducido]]-(Table_1[[#This Row],[Surtido Reducido]]*$M$4) -> 208221.45 | I10: 2 | J10: 179 | K10: =+HYPERLINK(Q10,"IR - Comprar y/o Personalizar") -> IR - Comprar y/o Personalizar | Q10: https://www.fabricamaxifer.com/resortes-lf.html
B11: RES. LA | C11: Resortes La | D11: 371796 | E11: =+'NUESTROS COMBOS'!$D11-('NUESTROS COMBOS'!$D11*$M$4) -> 200769.84 | F11: 3 | G11: 268464 | H11: =+Table_1[[#This Row],[Surtido Reducido]]-(Table_1[[#This Row],[Surtido Reducido]]*$M$4) -> 144970.56 | I11: 2 | J11: 104 | K11: =+HYPERLINK(Q11,"IR - Comprar y/o Personalizar") -> IR - Comprar y/o Personalizar | Q11: https://www.fabricamaxifer.com/resortes-la.html
B12: RES. LC | C12: Resortes Lc | D12: 689359.04 | E12: =+'NUESTROS COMBOS'!$D12-('NUESTROS COMBOS'!$D12*$M$4) -> 372253.88 | F12: 4 | G12: 389679.52 | H12: =+Table_1[[#This Row],[Surtido Reducido]]-(Table_1[[#This Row],[Surtido Reducido]]*$M$4) -> 210426.94 | I12: 2 | J12: 223 | K12: =+HYPERLINK(Q12,"IR - Comprar y/o Personalizar") -> IR - Comprar y/o Personalizar | Q12: https://www.fabricamaxifer.com/resortes-lc.html
B13: RES. LP | C13: Resortes Lp | D13: 817647 | E13: =+'NUESTROS COMBOS'!$D13-('NUESTROS COMBOS'!$D13*$M$4) -> 441529.38 | F13: 3 | G13: 570098 | H13: =+Table_1[[#This Row],[Surtido Reducido]]-(Table_1[[#This Row],[Surtido Reducido]]*$M$4) -> 307852.92 | I13: 2 | J13: 80 | K13: =+HYPERLINK(Q13,"IR - Comprar y/o Personalizar") -> IR - Comprar y/o Personalizar | Q13: https://www.fabricamaxifer.com/resortes-lp.html
B14: RES. LB | C14: Resortes Lb | D14: 564024.96 | E14: =+'NUESTROS COMBOS'!$D14-('NUESTROS COMBOS'!$D14*$M$4) -> 304573.48 | F14: 3 | G14: 406016.64 | H14: =+Table_1[[#This Row],[Surtido Reducido]]-(Table_1[[#This Row],[Surtido Reducido]]*$M$4) -> 219248.99 | I14: 2 | J14: 77 | K14: =+HYPERLINK(Q14,"IR - Comprar y/o Personalizar") -> IR - Comprar y/o Personalizar | Q14: https://www.fabricamaxifer.com/resortes-lb.html
B15: GA+CH COMP. | C15: Ganchos - Chavetas / Completo | D15: 424440.67 | E15: =+'NUESTROS COMBOS'!$D15-('NUESTROS COMBOS'!$D15*$M$4) -> 229197.96 | F15: 3 - 5 - 2 | G15: 320223.41 | H15: =+Table_1[[#This Row],[Surtido Reducido]]-(Table_1[[#This Row],[Surtido Reducido]]*$M$4) -> 172920.64 | I15: 3 | J15: 126 | K15: =+HYPERLINK(Q15,"IR - Comprar y/o Personalizar") -> IR - Comprar y/o Personalizar | Q15: https://www.fabricamaxifer.com/ganchos-chavetas-completo.html
B16: GAN. + CHA. | C16: Ganchos - Chavetas | D16: 233471.52 | E16: =+'NUESTROS COMBOS'!$D16-('NUESTROS COMBOS'!$D16*$M$4) -> 126074.62 | F16: 4 - 6 - 10 - 3 | G16: 165732.72 | H16: =+Table_1[[#This Row],[Surtido Reducido]]-(Table_1[[#This Row],[Surtido Reducido]]*$M$4) -> 89495.669 | I16: 3 | J16: 75 | K16: =+HYPERLINK(Q16,"IR - Comprar y/o Personalizar") -> IR - Comprar y/o Personalizar | Q16: https://www.fabricamaxifer.com/ganchos-chavetas.html
... B71: TR Espec. + Torn. | C71: Tornillos Especiales + Tr Completo | D71: 816791.5 | E71: =+'NUESTROS COMBOS'!$D71-('NUESTROS COMBOS'!$D71*$M$4) -> 441067.41 | F71: 5 | G71: 528074.9 | H71: =+Table_1[[#This Row],[Surtido Reducido]]-(Table_1[[#This Row],[Surtido Reducido]]*$M$4) -> 285160.45 | I71: 3 | J71: 402 | K71: =+HYPERLINK(Q71,"IR - Comprar y/o Personalizar") -> IR - Comprar y/o Personalizar | Q71: https://www.fabricamaxifer.com/tornillos-especiales-y-tuercas-rapidas-completo.html
B73: * Los precios no incluyen IVA ** 1 pieza va en el exhibidor

Sheet BD
A1: ID | B1: Producto | C1: Numero | D1: Descripción | E1: Precio | F1: Codigo | H1: Orden Productos
A2: =+Table_2[[#This Row],[Producto]]&Table_2[[#This Row],[Numero]] -> PLASTICOS1 | B2: PLASTICOS | C2: 1 | D2: Grampa tapizado R11- R18 | E2: =+VLOOKUP(Table_2[[#This Row],[ID]],LISTAS[],3,0) -> 1159.02 | F2: 039.039.0003 | G2: 1 | H2: PLASTICOS
A3: =+Table_2[[#This Row],[Producto]]&Table_2[[#This Row],[Numero]] -> PLASTICOS2 | B3: PLASTICOS | C3: 2 | D3: Grampa tapizadoDuna-128-147 | E3: =+VLOOKUP(Table_2[[#This Row],[ID]],LISTAS[],3,0) -> 578.93 | F3: 039.039.0004 | G3: =+G2+1 -> 2 | H3: RESORTES LINEA FERRETERIA
A4: =+Table_2[[#This Row],[Producto]]&Table_2[[#This Row],[Numero]] -> PLASTICOS3 | B4: PLASTICOS | C4: 3 | D4: Tuerca autorros. FIAT-RENAULT | E4: =+VLOOKUP(Table_2[[#This Row],[ID]],LISTAS[],3,0) -> 629.53 | F4: 039.039.0005 | G4: =+G3+1 -> 3 | H4: RESORTES LINEA COMPLEMENTARIA
A5: =+Table_2[[#This Row],[Producto]]&Table_2[[#This Row],[Numero]] -> PLASTICOS4 | B5: PLASTICOS | C5: 4 | D5: Fijacion consola GACELL | E5: =+VLOOKUP(Table_2[[#This Row],[ID]],LISTAS[],3,0) -> 654.85 | F5: 039.039.0006 | G5: =+G4+1 -> 4 | H5: RESORTES LINEA PESADA
A6: =+Table_2[[#This Row],[Producto]]&Table_2[[#This Row],[Numero]] -> PLASTICOS5 | B6: PLASTICOS | C6: 5 | D6: Fijacion OPTICA 128 | E6: =+VLOOKUP(Table_2[[#This Row],[ID]],LISTAS[],3,0) -> 727.61 | F6: 039.039.0007 | G6: =+G5+1 -> 5 | H6: RESORTES LINEA BULONERA
A7: =+Table_2[[#This Row],[Producto]]&Table_2[[#This Row],[Numero]] -> PLASTICOS6 | B7: PLASTICOS | C7: 6 | D7: Tuerca autorros. GACELL | E7: =+VLOOKUP(Table_2[[#This Row],[ID]],LISTAS[],3,0) -> 914.71 | F7: 039.039.0008 | G7: =+G6+1 -> 6 | H7: RESORTES LINEA AUTOMOTOR
A8: =+Table_2[[#This Row],[Producto]]&Table_2[[#This Row],[Numero]] -> PLASTICOS7 | B8: PLASTICOS | C8: 7 | D8: Fijacion patente FIAT | E8: =+VLOOKUP(Table_2[[#This Row],[ID]],LISTAS[],3,0) -> 578.93 | F8: 039.039.0009 | G8: =+G7+1 -> 7 | H8: RESORTES LINEA HORNO
A9: =+Table_2[[#This Row],[Producto]]&Table_2[[#This Row],[Numero]] -> PLASTICOS8 | B9: PLASTICOS | C9: 8 | D9: Registro faro 125 | E9: =+VLOOKUP(Table_2[[#This Row],[ID]],LISTAS[],3,0) -> 654.85 | F9: 039.039.0010 | G9: =+G8+1 -> 8 | H9: ORING
A10: =+Table_2[[#This Row],[Producto]]&Table_2[[#This Row],[Numero]] -> PLASTICOS9 | B10: PLASTICOS | C10: 9 | D10: Tuerca autorroscante FIAT | E10: =+VLOOKUP(Table_2[[#This Row],[ID]],LISTAS[],3,0) -> 680.9 | F10: 039.039.0011 | G10: =+G9+1 -> 9 | H10: CARBONES
A11: =+Table_2[[#This Row],[Producto]]&Table_2[[#This Row],[Numero]] -> PLASTICOS10 | B11: PLASTICOS | C11: 10 | D11: Fijacion capot 125 | E11: =+VLOOKUP(Table_2[[#This Row],[ID]],LISTAS[],3,0) -> 771.26 | F11: 039.039.0012 | G11: =+G10+1 -> 10 | H11: TERMINALES
A12: =+Table_2[[#This Row],[Producto]]&Table_2[[#This Row],[Numero]] -> PLASTICOS11 | B12: PLASTICOS | C12: 11 | D12: Tuerca parrilla DUNA- UNO | E12: =+VLOOKUP(Table_2[[#This Row],[ID]],LISTAS[],3,0) -> 917.77 | F12: 039.039.0013 | G12: =+G11+1 -> 11 | H12: REGATONES
A13: =+Table_2[[#This Row],[Producto]]&Table_2[[#This Row],[Numero]] -> PLASTICOS12 | B13: PLASTICOS | C13: 12 | D13: Tuerca autorroc. PEUGEOT | E13: =+VLOOKUP(Table_2[[#This Row],[ID]],LISTAS[],3,0) -> 933.24 | F13: 039.039.0014 | G13: =+G12+1 -> 12 | H13: ARANDELAS DE GOMA
A14: =+Table_2[[#This Row],[Producto]]&Table_2[[#This Row],[Numero]] -> PLASTICOS13 | B14: PLASTICOS | C14: 13 | D14: Tuerca autorros. FIAT-PEUGEOT | E14: =+VLOOKUP(Table_2[[#This Row],[ID]],LISTAS[],3,0) -> 1202.08 | F14: 039.039.0015 | G14: =+G13+1 -> 13 | H14: ARANDELAS DE GOMA LINEA PESADA
... A56: =+Table_2[[#This Row],[Producto]]&Table_2[[#This Row],[Numero]] -> PLASTICOS55 | B56: PLASTICOS | C56: 55 | D56: Grampa varilla cerradura FIAT DUNA UNO | E56: =+VLOOKUP(Table_2[[#This Row],[ID]],LISTAS[],3,0) -> 778.17 | F56: 039.039.0057 | G56: =+G55+1 -> 55 | H56: TUERCAS RAPIDAS NUEVAS
A57: =+Table_2[[#This Row],[Producto]]&Table_2[[#This Row],[Numero]] -> PLASTICOS56 | B57: PLASTICOS | C57: 56 | D57: Buje insignia FIAT UNO-DUNA | E57: =+VLOOKUP(Table_2[[#This Row],[ID]],LISTAS[],3,0) -> 578.93 | F57: 039.039.0058 | G57: 56 | H57: CONECTORES DE COMBUSTIBLE
A58: =+Table_2[[#This Row],[Producto]]&Table_2[[#This Row],[Numero]] -> PLASTICOS57 | B58: PLASTICOS | C58: 57 | D58: Tuerca apoya brazo VOLKSWEGEN GACELL | E58: =+VLOOKUP(Table_2[[#This Row],[ID]],LISTAS[],3,0) -> 1845.05 | F58: 039.039.0059
A59: =+Table_2[[#This Row],[Producto]]&Table_2[[#This Row],[Numero]] -> PLASTICOS58 | B59: PLASTICOS | C59: 58 | D59: Grampa bagueta zocalo R11 | E59: =+VLOOKUP(Table_2[[#This Row],[ID]],LISTAS[],3,0) -> 1088.84 | F59: 039.039.0060
A60: =+Table_2[[#This Row],[Producto]]&Table_2[[#This Row],[Numero]] -> PLASTICOS59 | B60: PLASTICOS | C60: 59 | D60: Grampa bagueta zocalo R11 | E60: =+VLOOKUP(Table_2[[#This Row],[ID]],LISTAS[],3,0) -> 964.7 | F60: 039.039.0061
A61: =+Table_2[[#This Row],[Producto]]&Table_2[[#This Row],[Numero]] -> PLASTICOS60 | B61: PLASTICOS | C61: 60 | D61: Grampa bagueta zocalo R11 roja | E61: =+VLOOKUP(Table_2[[#This Row],[ID]],LISTAS[],3,0) -> 964.7 | F61: 039.039.0062
A62: =+Table_2[[#This Row],[Producto]]&Table_2[[#This Row],[Numero]] -> PLASTICOS61 | B62: PLASTICOS | C62: 61 | D62: grampa varilla cerradura FIAT 600 - PEUGEOT | E62: =+VLOOKUP(Table_2[[#This Row],[ID]],LISTAS[],3,0) -> 910.22 | F62: 039.039.0063
A63: =+Table_2[[#This Row],[Producto]]&Table_2[[#This Row],[Numero]] -> PLASTICOS62 | B63: PLASTICOS | C63: 62 | D63: Grampa tapizado Renault 21 | E63: =+VLOOKUP(Table_2[[#This Row],[ID]],LISTAS[],3,0) -> 1027.04 | F63: 039.039.0064
A64: =+Table_2[[#This Row],[Producto]]&Table_2[[#This Row],[Numero]] -> PLASTICOS63 | B64: PLASTICOS | C64: 63 | D64: Grampa paragolpe Ford Ka | E64: =+VLOOKUP(Table_2[[#This Row],[ID]],LISTAS[],3,0) -> 1244.49 | F64: 039.039.0065
A65: =+Table_2[[#This Row],[Producto]]&Table_2[[#This Row],[Numero]] -> PLASTICOS64 | B65: PLASTICOS | C65: 64 | D65: Grampa tapizado Renault 19 | E65: =+VLOOKUP(Table_2[[#This Row],[ID]],LISTAS[],3,0) -> 1186.46 | F65: 039.039.0066
A66: =+Table_2[[#This Row],[Producto]]&Table_2[[#This Row],[Numero]] -> PLASTICOS65 | B66: PLASTICOS | C66: 65 | D66: Grampa tapizado Peugeot 405 larga | E66: =+VLOOKUP(Table_2[[#This Row],[ID]],LISTAS[],3,0) -> 1027.04 | F66: 039.039.0067
A67: =+Table_2[[#This Row],[Producto]]&Table_2[[#This Row],[Numero]] -> PLASTICOS66 | B67: PLASTICOS | C67: 66 | D67: Grampa tapizado puerta Chevr. Corsa | E67: =+VLOOKUP(Table_2[[#This Row],[ID]],LISTAS[],3,0) -> 756.71 | F67: 039.039.0068
A68: =+Table_2[[#This Row],[Producto]]&Table_2[[#This Row],[Numero]] -> PLASTICOS67 | B68: PLASTICOS | C68: 67 | D68: Grampa tapizado Ford Ka | E68: =+VLOOKUP(Table_2[[#This Row],[ID]],LISTAS[],3,0) -> 1244.49 | F68: 039.039.0069
A69: =+Table_2[[#This Row],[Producto]]&Table_2[[#This Row],[Numero]] -> PLASTICOS69 | B69: PLASTICOS | C69: 69 | D69: Grampa pasacable omega grande | E69: =+VLOOKUP(Table_2[[#This Row],[ID]],LISTAS[],3,0) -> 683.78 | F69: 039.039.0070
... A1084: =+Table_2[[#This Row],[Producto]]&Table_2[[#This Row],[Numero]] -> ORING402 | B1084: ORING | C1084: 402 | D1084: Cuerda 5,30mm - Nitrilo | E1084: =+VLOOKUP(Table_2[[#This Row],[ID]],LISTAS[],3,0) -> 4474.8 | F1084: 036.036.0151
A1085: =+Table_2[[#This Row],[Producto]]&Table_2[[#This Row],[Numero]] -> INSERTOS4X6 | B1085: INSERTOS | C1085: 4X6 | D1085: 4X6 | E1085: =+VLOOKUP(Table_2[[#This Row],[ID]],LISTAS[],3,0) -> 1861.56 | F1085: 031.031.0003
A1086: =+Table_2[[#This Row],[Producto]]&Table_2[[#This Row],[Numero]] -> INSERTOS5X7 | B1086: INSERTOS | C1086: 5X7 | D1086: 5X7 | E1086: =+VLOOKUP(Table_2[[#This Row],[ID]],LISTAS[],3,0) -> 1861.56 | F1086: 031.031.0004
A1087: =+Table_2[[#This Row],[Producto]]&Table_2[[#This Row],[Numero]] -> INSERTOS6X8 | B1087: INSERTOS | C1087: 6X8 | D1087: 6X8 | E1087: =+VLOOKUP(Table_2[[#This Row],[ID]],LISTAS[],3,0) -> 1861.56 | F1087: 031.031.0005
A1088: =+Table_2[[#This Row],[Producto]]&Table_2[[#This Row],[Numero]] -> INSERTOS7X10 | B1088: INSERTOS | C1088: 7X10 | D1088: 7X10 | E1088: =+VLOOKUP(Table_2[[#This Row],[ID]],LISTAS[],3,0) -> 1861.56 | F1088: 031.031.0006
A1089: =+Table_2[[#This Row],[Producto]]&Table_2[[#This Row],[Numero]] -> INSERTOS8X1X11 | B1089: INSERTOS | C1089: 8X1X11 | D1089: 8X1X11 | E1089: =+VLOOKUP(Table_2[[#This Row],[ID]],LISTAS[],3,0) -> 1861.56 | F1089: 031.031.0007
A1090: =+Table_2[[#This Row],[Producto]]&Table_2[[#This Row],[Numero]] -> INSERTOS8X11 | B1090: INSERTOS | C1090: 8X11 | D1090: 8X11 | E1090: =+VLOOKUP(Table_2[[#This Row],[ID]],LISTAS[],3,0) -> 1861.56 | F1090: 031.031.0008
A1091: =+Table_2[[#This Row],[Producto]]&Table_2[[#This Row],[Numero]] -> INSERTOS9X12 | B1091: INSERTOS | C1091: 9X12 | D1091: 9X12 | E1091: =+VLOOKUP(Table_2[[#This Row],[ID]],LISTAS[],3,0) -> 1861.56 | F1091: 031.031.0009
A1092: =+Table_2[[#This Row],[Producto]]&Table_2[[#This Row],[Numero]] -> INSERTOS10X1X1/2 | B1092: INSERTOS | C1092: 10X1X1/2 | D1092: 10X1X1/2 | E1092: =+VLOOKUP(Table_2[[#This Row],[ID]],LISTAS[],3,0) -> 1861.56 | F1092: 031.031.0010
A1093: =+Table_2[[#This Row],[Producto]]&Table_2[[#This Row],[Numero]] -> INSERTOS10X1,25X1/2 | B1093: INSERTOS | C1093: 10X1,25X1/2 | D1093: 10X1,25X1/2 | E1093: =+VLOOKUP(Table_2[[#This Row],[ID]],LISTAS[],3,0) -> 1861.56 | F1093: 031.031.0011
A1094: =+Table_2[[#This Row],[Producto]]&Table_2[[#This Row],[Numero]] -> INSERTOS10x1,5x1/2 | B1094: INSERTOS | C1094: 10x1,5x1/2 | D1094: 10x1,5x1/2 | E1094: =+VLOOKUP(Table_2[[#This Row],[ID]],LISTAS[],3,0) -> 1861.56 | F1094: 031.031.0012
A1095: =+Table_2[[#This Row],[Producto]]&Table_2[[#This Row],[Numero]] -> INSERTOS11x14 | B1095: INSERTOS | C1095: 11x14 | D1095: 11x14 | E1095: =+VLOOKUP(Table_2[[#This Row],[ID]],LISTAS[],3,0) -> 2349.2 | F1095: 031.031.0013
...

Sheet LISTAS
A1: ID | B1: Codigo BS GESTION | C1: Precio
A2: PLASTICOS1 | B2: 039.039.0003 | C2: 1159.02
A3: PLASTICOS2 | B3: 039.039.0004 | C3: 578.93
A4: PLASTICOS3 | B4: 039.039.0005 | C4: 629.53
A5: PLASTICOS4 | B5: 039.039.0006 | C5: 654.85
A6: PLASTICOS5 | B6: 039.039.0007 | C6: 727.61
A7: PLASTICOS6 | B7: 039.039.0008 | C7: 914.71
A8: PLASTICOS7 | B8: 039.039.0009 | C8: 578.93
A9: PLASTICOS8 | B9: 039.039.0010 | C9: 654.85
A10: PLASTICOS9 | B10: 039.039.0011 | C10: 680.9
A11: PLASTICOS10 | B11: 039.039.0012 | C11: 771.26
A12: PLASTICOS11 | B12: 039.039.0013 | C12: 917.77
A13: PLASTICOS12 | B13: 039.039.0014 | C13: 933.24
... A2079: CARBONES109 - 13,7 x 7 x 6 | B2079: 020.020.0042 | C2079: 5979.93
A2080: CARBONESExhibidor | C2080: 0
A2081: KIT RIFLE5/2 máster Potenciado + Pistón + Arandela | B2081: 033.033.0003 | C2081: 0
A2082: KIT RIFLEMáster Potenciado Coop + Pistón + Arandela | B2082: 033.033.0004 | C2082: 0
A2083: KIT RIFLEJunior + Pistón + Arandela | B2083: 033.033.0005 | C2083: 0
A2084: ESPINAS ELASTICAS2 x 12 | B2084: 028.028.0003 | C2084: 52.79
A2085: ESPINAS ELASTICAS2 x 16 | B2085: 028.028.0004 | C2085: 70.39
A2086: ESPINAS ELASTICAS2 x 20 | B2086: 028.028.0005 | C2086: 87.97
A2087: ESPINAS ELASTICAS2,5 x 14 | B2087: 028.028.0006 | C2087: 77.18
A2088: ESPINAS ELASTICAS2,5 x 16 | B2088: 028.028.0007 | C2088: 88.17
A2089: ESPINAS ELASTICAS2,5 x 26 | B2089: 028.028.0008 | C2089: 143.31
A2090: ESPINAS ELASTICAS2,5 x 30 | B2090: 028.028.0009 | C2090: 165.43
A2091: ESPINAS ELASTICAS3 x 14 | B2091: 028.028.0010 | C2091: 94.37
A2092: ESPINAS ELASTICAS3 x 16 | B2092: 028.028.0011 | C2092: 121.36
... A2436: CONECTORES NEUMÁTICOS228 | B2436: 023.023.0069 | C2436: 1212.48
A2437: CONECTORES NEUMÁTICOS229 | B2437: 023.023.0070 | C2437: 2556.43 | I2437: 063.063.0028
A2438: CONECTORES NEUMÁTICOS230 | B2438: 023.023.0071 | C2438: 2850.1 | I2438: 063.063.0029
A2439: CONECTORES NEUMÁTICOS231 | B2439: 023.023.0072 | C2439: 3953.83 | I2439: 063.063.0030
A2440: CONECTORES NEUMÁTICOS49 | B2440: 023.023.0073 | C2440: 0 | I2440: 063.063.0031
A2441: CONECTORES NEUMÁTICOS51 | B2441: 023.023.0074 | C2441: 0 | I2441: 063.063.0032
A2442: CONECTORES NUEVA INCORPORACION3 | B2442: 024.024.0003 | C2442: 3239.17 | I2442: 017.017.0003
A2443: CONECTORES NUEVA INCORPORACION7 | B2443: 024.024.0004 | C2443: 4356.83 | I2443: 017.017.0004
A2444: CONECTORES NUEVA INCORPORACION96 | B2444: 024.024.0005 | C2444: 1224.17 | I2444: 017.017.0005
A2445: CONECTORES NUEVA INCORPORACION107 | B2445: 024.024.0006 | C2445: 3154.29 | I2445: 017.017.0006
A2446: CONECTORES NUEVA INCORPORACION139 | B2446: 024.024.0007 | C2446: 1283.17 | I2446: 017.017.0007
A2447: CONECTORES NUEVA INCORPORACION152 | B2447: 024.024.0008 | C2447: 3540.97 | I2447: 017.017.0008
A2448: CONECTORES NUEVA INCORPORACION156 | B2448: 024.024.0009 | C2448: 3925.98 | I2448: 017.017.0009
...

Sheet Imagen
A1: ID | B1: IMAGEN
A2: PLASTICOS1 | B2: http://http2.mlstatic.com/D_708492-MLA72045130481_102023-F.jpg
A3: PLASTICOS2 | B3: http://http2.mlstatic.com/D_785905-MLA71988387406_102023-F.jpg
A4: PLASTICOS3 | B4: http://http2.mlstatic.com/D_878027-MLA72239756252_102023-F.jpg
A5: PLASTICOS4 | B5: http://http2.mlstatic.com/D_741302-MLA71988387408_102023-F.jpg
A6: PLASTICOS5 | B6: http://http2.mlstatic.com/D_986792-MLA72240891774_102023-F.jpg
A7: PLASTICOS6 | B7: http://http2.mlstatic.com/D_953256-MLA71988435968_102023-F.jpg
A8: PLASTICOS7 | B8: http://http2.mlstatic.com/D_778884-MLA71988387412_102023-F.jpg
A9: PLASTICOS8 | B9: http://http2.mlstatic.com/D_881846-MLA71988387472_102023-F.jpg
A10: PLASTICOS9 | B10: http://http2.mlstatic.com/D_647342-MLA72293218763_102023-F.jpg
A11: PLASTICOS10 | B11: http://http2.mlstatic.com/D_724144-MLA72292952705_102023-F.jpg
A12: PLASTICOS11 | B12: http://http2.mlstatic.com/D_790405-MLA72292952961_102023-F.jpg
... A14: PLASTICOS13 | B14: http://http2.mlstatic.com/D_868791-MLA71988436048_102023-F.jpg
A15: PLASTICOS14
A16: PLASTICOS15 | B16: http://http2.mlstatic.com/D_849599-MLA72045130573_102023-F.jpg
A17: PLASTICOS16 | B17: http://http2.mlstatic.com/D_759357-MLA71988436056_102023-F.jpg
A18: PLASTICOS17 | B18: http://http2.mlstatic.com/D_784053-MLA71988436060_102023-F.jpg
A19: PLASTICOS18 | B19: http://http2.mlstatic.com/D_767299-MLA71988387492_102023-F.jpg
A20: PLASTICOS19 | B20: http://http2.mlstatic.com/D_633062-MLA72045130585_102023-F.jpg
A21: PLASTICOS20 | B21: http://http2.mlstatic.com/D_651074-MLA71988387494_102023-F.jpg
A22: PLASTICOS21 | B22: http://http2.mlstatic.com/D_915039-MLA72045130587_102023-F.jpg
A23: PLASTICOS22 | B23: http://http2.mlstatic.com/D_808914-MLA71988436066_102023-F.jpg
A24: PLASTICOS23 | B24: http://http2.mlstatic.com/D_795009-MLA72045130593_102023-F.jpg
A25: PLASTICOS24 | B25: http://http2.mlstatic.com/D_839604-MLA72304258543_102023-F.jpg
A26: PLASTICOS25 | B26: http://http2.mlstatic.com/D_982789-MLA71988387498_102023-F.jpg
A27: PLASTICOS26 | B27: http://http2.mlstatic.com/D_939078-MLA72045130601_102023-F.jpg
... A49: PLASTICOS48 | B49: http://http2.mlstatic.com/D_910527-MLA71988436122_102023-F.jpg
A50: PLASTICOS49
A51: PLASTICOS50 | B51: http://http2.mlstatic.com/D_874828-MLA71988436130_102023-F.jpg
A52: PLASTICOS51 | B52: http://http2.mlstatic.com/D_949801-MLA72045130647_102023-F.jpg
A53: PLASTICOS52 | B53: http://http2.mlstatic.com/D_704935-MLA72045130649_102023-F.jpg
A54: PLASTICOS53 | B54: http://http2.mlstatic.com/D_618901-MLA72292972649_102023-F.jpg
A55: PLASTICOS54 | B55: http://http2.mlstatic.com/D_723830-MLA71988436146_102023-F.jpg
A56: PLASTICOS55 | B56: http://http2.mlstatic.com/D_915339-MLA71988436142_102023-F.jpg
A57: PLASTICOS56 | B57: http://http2.mlstatic.com/D_681688-MLA72292952709_102023-F.jpg
A58: PLASTICOS57
A59: PLASTICOS58 | B59: http://http2.mlstatic.com/D_630670-MLA71988387564_102023-F.jpg
A60: PLASTICOS59 | B60: http://http2.mlstatic.com/D_614810-MLA72409121524_102023-F.jpg
A61: PLASTICOS60 | B61: http://http2.mlstatic.com/D_859108-MLA71988387576_102023-F.jpg
A62: PLASTICOS61 | B62: http://http2.mlstatic.com/D_702377-MLA71988387574_102023-F.jpg
...
